2024-05-06 20:08:52,375 - ERROR - Task exception was never retrieved
future: <Task finished name='Task-3' coro=<run_cli() done, defined at C:\Users\xbox2\Downloads\CMP2804\SQL_Integration\main.py:28> exception=EOFError()>
Traceback (most recent call last):
  File "C:\Users\xbox2\Downloads\CMP2804\SQL_Integration\main.py", line 30, in run_cli
    await asyncio.to_thread(cli.run)
  File "C:\Users\xbox2\AppData\Local\Programs\Python\Python312\Lib\asyncio\threads.py", line 25, in to_thread
    return await loop.run_in_executor(None, func_call)
           ^^^^^^^^^^^^^^^^^^^^^^^^^^^^^^^^^^^^^^^^^^^
  File "C:\Users\xbox2\AppData\Local\Programs\Python\Python312\Lib\concurrent\futures\thread.py", line 58, in run
    result = self.fn(*self.args, **self.kwargs)
             ^^^^^^^^^^^^^^^^^^^^^^^^^^^^^^^^^^
  File "C:\Users\xbox2\Downloads\CMP2804\SQL_Integration\interface_handling\User_CLI.py", line 61, in run
    data = self.collect_data()
           ^^^^^^^^^^^^^^^^^^^
  File "C:\Users\xbox2\Downloads\CMP2804\SQL_Integration\interface_handling\User_CLI.py", line 17, in collect_data
    ip = self.validate_ip(input("Enter IP address: "))
                          ^^^^^^^^^^^^^^^^^^^^^^^^^^^
EOFError
2024-05-07 12:40:00,083 - ERROR - Task exception was never retrieved
future: <Task finished name='Task-3' coro=<run_cli() done, defined at C:\Users\xbox2\Downloads\CMP2804\SQL_Integration\Main.py:38> exception=EOFError()>
Traceback (most recent call last):
  File "C:\Users\xbox2\Downloads\CMP2804\SQL_Integration\Main.py", line 40, in run_cli
    await asyncio.to_thread(cli.run)
  File "C:\Users\xbox2\AppData\Local\Programs\Python\Python312\Lib\asyncio\threads.py", line 25, in to_thread
    return await loop.run_in_executor(None, func_call)
           ^^^^^^^^^^^^^^^^^^^^^^^^^^^^^^^^^^^^^^^^^^^
  File "C:\Users\xbox2\AppData\Local\Programs\Python\Python312\Lib\concurrent\futures\thread.py", line 58, in run
    result = self.fn(*self.args, **self.kwargs)
             ^^^^^^^^^^^^^^^^^^^^^^^^^^^^^^^^^^
  File "C:\Users\xbox2\Downloads\CMP2804\SQL_Integration\interface_handling\User_CLI.py", line 61, in run
    data = self.collect_data()
           ^^^^^^^^^^^^^^^^^^^
  File "C:\Users\xbox2\Downloads\CMP2804\SQL_Integration\interface_handling\User_CLI.py", line 17, in collect_data
    ip = self.validate_ip(input("Enter IP address: "))
                          ^^^^^^^^^^^^^^^^^^^^^^^^^^^
EOFError
2024-05-07 12:42:58,356 - ERROR - Task exception was never retrieved
future: <Task finished name='Task-3' coro=<run_cli() done, defined at C:\Users\xbox2\Downloads\CMP2804\SQL_Integration\Main.py:38> exception=EOFError()>
Traceback (most recent call last):
  File "C:\Users\xbox2\Downloads\CMP2804\SQL_Integration\Main.py", line 40, in run_cli
    await asyncio.to_thread(cli.run)
  File "C:\Users\xbox2\AppData\Local\Programs\Python\Python312\Lib\asyncio\threads.py", line 25, in to_thread
    return await loop.run_in_executor(None, func_call)
           ^^^^^^^^^^^^^^^^^^^^^^^^^^^^^^^^^^^^^^^^^^^
  File "C:\Users\xbox2\AppData\Local\Programs\Python\Python312\Lib\concurrent\futures\thread.py", line 58, in run
    result = self.fn(*self.args, **self.kwargs)
             ^^^^^^^^^^^^^^^^^^^^^^^^^^^^^^^^^^
  File "C:\Users\xbox2\Downloads\CMP2804\SQL_Integration\interface_handling\User_CLI.py", line 61, in run
    data = self.collect_data()
           ^^^^^^^^^^^^^^^^^^^
  File "C:\Users\xbox2\Downloads\CMP2804\SQL_Integration\interface_handling\User_CLI.py", line 17, in collect_data
    ip = self.validate_ip(input("Enter IP address: "))
                          ^^^^^^^^^^^^^^^^^^^^^^^^^^^
EOFError
